<robot name="plane" xmlns:xacro="http://www.ros.org/wiki/xacro">

    <link name="body_FLU">
        <visual>
            <origin rpy="0 -1.57 0 " />
            <geometry>
                <cylinder radius="0.5" length="2.5" />
            </geometry>
        </visual>

        <collision>
            <origin rpy="0 -1.57 0 " />
            <geometry>
                <cylinder radius="0.5" length="2.5" />
            </geometry>
        </collision>

        <inertial>
            <origin rpy="0 -1.57 0 " />
            <mass value="0.2" />
            <inertia ixx="0.116666666666" ixy="0" ixz="0" iyz="0"
                iyy="0.116666666666" izz="0.00416666666666" />
        </inertial>

    </link>
    ----------------------------------------------------------------------------  wings
    
    
    <link name="airfoil">
        <visual>
            <geometry>
                <box size="0.5 6 0.1" />
            </geometry>
        </visual>

        <collision>
            <geometry>
                <box size="0.5 6 0.1" />
            </geometry>
        </collision>


        <inertial>
            <mass value="2" />
            <inertia ixx="6.0016666666666" ixy="0" ixz="0" iyz="0"
                iyy="0.04333333333333" izz="6.0416666666666" />
        </inertial>
    </link>
    
    <joint name="body_FLUToWing" type="revolute">
        <origin xyz="0 0 0" rpy ="0 0 0"/>
        <parent link="body_FLU" />
        <child link="airfoil" />
        <limit effort="1000.0" lower="-0.000872665" upper="0.000872665" velocity="0.5"/>
    </joint>
    
 -----------------------------------------------------------------------------------propeller
    
    <link name="arm">
        <visual>
            <origin xyz="0 0 0.1" />
            <geometry>
                <cylinder radius="0.1" length="0.2" />
            </geometry>
        </visual>

        <collision>
            <origin xyz="0 0 0.1" />
            <geometry>
                <cylinder radius="0.1" length="0.2" />
            </geometry>
        </collision>

        <inertial>
            <origin xyz="0 0 0.1" />
            <mass value="0.1" />
            <inertia ixx="0.000583333" ixy="0" ixz="0" iyz="0"
                iyy="0.000583333" izz="0.00008333333" />
        </inertial>
    </link>

    <joint name="body_FLU_to_arm" type="continuous">
        <origin xyz="1.25 0 0" rpy="0 1.57  0" />
        <axis xyz="0 0 1" />
        <parent link="body_FLU" />
        <child link="arm" />
    </joint>


    <link name="propeller">
        <visual>
            <geometry>
                <box size="0.8 0.2 0.05" />
            </geometry>
        </visual>

        <collision>
            <geometry>
                <box size="0.8 0.2 0.05" />
            </geometry>
        </collision>

        <inertial>
            <mass value="0.1" />
            <inertia ixx="0.00035416666666" ixy="0" ixz="0" iyz="0"
                iyy=" 0.005354166666666" izz="0.005666666666" />
        </inertial>

    </link>

    <joint name="arm_to_propeller" type="fixed">
        <origin xyz="0 0 0.2" rpy="0 0 0" />
        <parent link="arm" />
        <child link="propeller" />
    </joint>
    
     ---------------------------------------------------------------------------front wheels
     
    <link name="wheel_base">
        <visual>
            <geometry>
                <box size="0.05 2 0.05" />
            </geometry>
        </visual>

        <collision>
            <geometry>
                <box size="0.05 2 0.05" />
            </geometry>
        </collision>

        <inertial>
            <mass value="0.1" />
            <inertia ixx="0.033354166666" ixy="0" ixz="0" iyz="0"
                iyy=" 0.00004166666" izz="0.033354166666" />
        </inertial>

    </link>

    <joint name=" body_FLU_to_wheel_base" type="fixed">
        <origin xyz="1 0 -0.5" rpy="0 0 0" />
        <parent link="body_FLU" />
        <child link="wheel_base" />
    </joint>

    <link name="left_wheel">
        <visual>
            <origin xyz="0 0 0.05" />
            <geometry>
                <cylinder radius="0.3" length="0.1" />
            </geometry>
        </visual>

        <collision>
            <origin xyz="0 0 0.05" />
            <geometry>
                <cylinder radius="0.3" length="0.1" />
            </geometry>
        </collision>

        <inertial>
            <origin xyz="0 0 0.05" />
            <mass value="0.1" />
            <inertia ixx="0.0023333333333333" ixy="0" ixz="0" iyz="0"
                iyy=" 0.0023333333333333" izz="0.00075" />
        </inertial>
    </link>

    <joint name="wheel_base_to_left_wheel" type="continuous">
        <origin xyz="0 -1 0" rpy="1.57 0 0" />
        <parent link="wheel_base" />
        <child link="left_wheel" />
        <axis xyz=" 0 0 1" />
    </joint>


    <link name="right_wheel">
        <visual>
            <origin xyz="0 0 -0.05" />
            <geometry>
                <cylinder radius="0.3" length="0.1" />
            </geometry>
        </visual>

        <collision>
            <origin xyz="0 0 -0.05" />
            <geometry>
                <cylinder radius="0.3" length="0.1" />
            </geometry>
        </collision>

        <inertial>
            <origin xyz="0 0 -0.05" />
            <mass value="0.1" />
            <inertia ixx="0.0023333333333333" ixy="0" ixz="0" iyz="0"
                iyy=" 0.0023333333333333" izz="0.00075" />
        </inertial>
    </link>

    <joint name="wheel_base_to_right_wheel" type="continuous">
        <origin xyz="0 1 0" rpy="1.57 0 0" />
        <parent link="wheel_base" />
        <child link="right_wheel" />
        <axis xyz=" 0 0 1" />
    </joint>

    ------------------------------------------------------------------------------------ rear sphere wheel

    <link name="rear_wheel">
        <visual>
            <geometry>
                <sphere radius="0.1" />
            </geometry>
        </visual>

        <collision>
            <geometry>
                <sphere radius="0.1" />
            </geometry>
        </collision>

        <inertial>
            <mass value="0.1" />
            <inertia ixx="0.0004" ixy="0" ixz="0" iyz="0"
                iyy=" 0.0004" izz="0.0004" />
        </inertial>
    </link>

    <joint name="body_FLU_to_rear_wheel" type="continuous">
        <origin xyz="-1 0 -0.5" />
        <axis xyz="0 1 0"/>
        <parent link="body_FLU" />
        <child link="rear_wheel" />
    </joint>
    
    <gazebo>
    <plugin name="model_plugin" filename="libmodel_plugin.so"/>
    <plugin name="joint_state_publisher" filename="libgazebo_ros_joint_state_publisher.so">
        <jointName>body_FLUToWing, body_FLU_to_arm, wheel_base_to_left_wheel, wheel_base_to_right_wheel, body_FLU_to_rear_wheel </jointName>
        <robotNamespace>last_letter_2</robotNamespace>
        <updateRate>0</updateRate>
    </plugin>
  </gazebo>

</robot>